[2024-10-10 16:19:10] [INFO    ] discord.client: logging in using static token
[2024-10-10 16:19:10] [INFO    ] discord.gateway: Shard ID None has connected to Gateway (Session ID: 7c5250b8836853f365b0a930880c9381).
[2024-10-10 17:48:46] [ERROR   ] discord.client: Ignoring exception in on_message
Traceback (most recent call last):
  File "/mnt/2tbdrive/projects/RoyBot/venv/lib/python3.12/site-packages/discord/client.py", line 449, in _run_event
    await coro(*args, **kwargs)
  File "/mnt/2tbdrive/projects/RoyBot/src/main.py", line 19, in on_message
    await messages.handle_message(client, message)
  File "/mnt/2tbdrive/projects/RoyBot/src/handlers/messages.py", line 22, in handle_message
    image_generator.generate_message_jpg(original, message.author.display_name, message.author.display_avatar.url)
  File "/mnt/2tbdrive/projects/RoyBot/src/image_generator.py", line 44, in generate_message_jpg
    message_box.send_keys(message)
  File "/mnt/2tbdrive/projects/RoyBot/venv/lib/python3.12/site-packages/selenium/webdriver/remote/webelement.py", line 231, in send_keys
    self._execute(
  File "/mnt/2tbdrive/projects/RoyBot/venv/lib/python3.12/site-packages/selenium/webdriver/remote/webelement.py", line 395, in _execute
    return self._parent.execute(command, params)
           ^^^^^^^^^^^^^^^^^^^^^^^^^^^^^^^^^^^^^
  File "/mnt/2tbdrive/projects/RoyBot/venv/lib/python3.12/site-packages/selenium/webdriver/remote/webdriver.py", line 354, in execute
    self.error_handler.check_response(response)
  File "/mnt/2tbdrive/projects/RoyBot/venv/lib/python3.12/site-packages/selenium/webdriver/remote/errorhandler.py", line 229, in check_response
    raise exception_class(message, screen, stacktrace)
selenium.common.exceptions.WebDriverException: Message: unknown error: ChromeDriver only supports characters in the BMP
  (Session info: chrome=129.0.6668.100)
Stacktrace:
#0 0x634a1c5fdf8a <unknown>
#1 0x634a1c2e45e0 <unknown>
#2 0x634a1c3712d4 <unknown>
#3 0x634a1c32db8d <unknown>
#4 0x634a1c32ce66 <unknown>
#5 0x634a1c358b22 <unknown>
#6 0x634a1c328478 <unknown>
#7 0x634a1c358cee <unknown>
#8 0x634a1c377d7d <unknown>
#9 0x634a1c3588c3 <unknown>
#10 0x634a1c3266b3 <unknown>
#11 0x634a1c32768e <unknown>
#12 0x634a1c5c898b <unknown>
#13 0x634a1c5cc911 <unknown>
#14 0x634a1c5b5185 <unknown>
#15 0x634a1c5cd492 <unknown>
#16 0x634a1c59a2ef <unknown>
#17 0x634a1c5ece88 <unknown>
#18 0x634a1c5ed053 <unknown>
#19 0x634a1c5fcddc <unknown>
#20 0x71a5e409ca94 <unknown>
#21 0x71a5e4129c3c <unknown>

[2024-10-10 18:21:12] [ERROR   ] discord.client: Ignoring exception in on_message
Traceback (most recent call last):
  File "/mnt/2tbdrive/projects/RoyBot/src/handlers/messages.py", line 33, in handle_message
    await message.reply(f"# ðŸš¨ROY ALERTðŸš¨\nroy #{roy_counter.roy_count}", file=discord.File(new_path))
  File "/mnt/2tbdrive/projects/RoyBot/venv/lib/python3.12/site-packages/discord/message.py", line 1564, in reply
    return await self.channel.send(content, reference=self, **kwargs)
           ^^^^^^^^^^^^^^^^^^^^^^^^^^^^^^^^^^^^^^^^^^^^^^^^^^^^^^^^^^
  File "/mnt/2tbdrive/projects/RoyBot/venv/lib/python3.12/site-packages/discord/abc.py", line 1618, in send
    data = await state.http.send_message(channel.id, params=params)
           ^^^^^^^^^^^^^^^^^^^^^^^^^^^^^^^^^^^^^^^^^^^^^^^^^^^^^^^^
  File "/mnt/2tbdrive/projects/RoyBot/venv/lib/python3.12/site-packages/discord/http.py", line 758, in request
    raise HTTPException(response, data)
discord.errors.HTTPException: 400 Bad Request (error code: 50035): Invalid Form Body
In message_reference: Unknown message

During handling of the above exception, another exception occurred:

Traceback (most recent call last):
  File "/mnt/2tbdrive/projects/RoyBot/venv/lib/python3.12/site-packages/discord/client.py", line 449, in _run_event
    await coro(*args, **kwargs)
  File "/mnt/2tbdrive/projects/RoyBot/src/main.py", line 19, in on_message
    await messages.handle_message(client, message)
  File "/mnt/2tbdrive/projects/RoyBot/src/handlers/messages.py", line 37, in handle_message
    await message.reply(f"# ðŸš¨ROY ALERTðŸš¨\nroy #{roy_counter.roy_count}")
  File "/mnt/2tbdrive/projects/RoyBot/venv/lib/python3.12/site-packages/discord/message.py", line 1564, in reply
    return await self.channel.send(content, reference=self, **kwargs)
           ^^^^^^^^^^^^^^^^^^^^^^^^^^^^^^^^^^^^^^^^^^^^^^^^^^^^^^^^^^
  File "/mnt/2tbdrive/projects/RoyBot/venv/lib/python3.12/site-packages/discord/abc.py", line 1618, in send
    data = await state.http.send_message(channel.id, params=params)
           ^^^^^^^^^^^^^^^^^^^^^^^^^^^^^^^^^^^^^^^^^^^^^^^^^^^^^^^^
  File "/mnt/2tbdrive/projects/RoyBot/venv/lib/python3.12/site-packages/discord/http.py", line 758, in request
    raise HTTPException(response, data)
discord.errors.HTTPException: 400 Bad Request (error code: 50035): Invalid Form Body
In message_reference: Unknown message
[2024-10-10 18:29:21] [INFO    ] discord.gateway: Shard ID None has successfully RESUMED session 7c5250b8836853f365b0a930880c9381.
[2024-10-10 19:56:54] [INFO    ] discord.gateway: Shard ID None has successfully RESUMED session 7c5250b8836853f365b0a930880c9381.
[2024-10-10 20:07:53] [ERROR   ] discord.client: Ignoring exception in on_message
Traceback (most recent call last):
  File "/mnt/2tbdrive/projects/RoyBot/venv/lib/python3.12/site-packages/discord/client.py", line 449, in _run_event
    await coro(*args, **kwargs)
  File "/mnt/2tbdrive/projects/RoyBot/src/main.py", line 19, in on_message
    await messages.handle_message(client, message)
  File "/mnt/2tbdrive/projects/RoyBot/src/handlers/messages.py", line 22, in handle_message
    image_generator.generate_message_jpg(original, message.author.display_name, message.author.display_avatar.url)
  File "/mnt/2tbdrive/projects/RoyBot/src/image_generator.py", line 44, in generate_message_jpg
    message_box.send_keys(message)
  File "/mnt/2tbdrive/projects/RoyBot/venv/lib/python3.12/site-packages/selenium/webdriver/remote/webelement.py", line 231, in send_keys
    self._execute(
  File "/mnt/2tbdrive/projects/RoyBot/venv/lib/python3.12/site-packages/selenium/webdriver/remote/webelement.py", line 395, in _execute
    return self._parent.execute(command, params)
           ^^^^^^^^^^^^^^^^^^^^^^^^^^^^^^^^^^^^^
  File "/mnt/2tbdrive/projects/RoyBot/venv/lib/python3.12/site-packages/selenium/webdriver/remote/webdriver.py", line 354, in execute
    self.error_handler.check_response(response)
  File "/mnt/2tbdrive/projects/RoyBot/venv/lib/python3.12/site-packages/selenium/webdriver/remote/errorhandler.py", line 229, in check_response
    raise exception_class(message, screen, stacktrace)
selenium.common.exceptions.WebDriverException: Message: unknown error: ChromeDriver only supports characters in the BMP
  (Session info: chrome=129.0.6668.100)
Stacktrace:
#0 0x6538001b6f8a <unknown>
#1 0x6537ffe9d5e0 <unknown>
#2 0x6537fff2a2d4 <unknown>
#3 0x6537ffee6b8d <unknown>
#4 0x6537ffee5e66 <unknown>
#5 0x6537fff11b22 <unknown>
#6 0x6537ffee1478 <unknown>
#7 0x6537fff11cee <unknown>
#8 0x6537fff30d7d <unknown>
#9 0x6537fff118c3 <unknown>
#10 0x6537ffedf6b3 <unknown>
#11 0x6537ffee068e <unknown>
#12 0x65380018198b <unknown>
#13 0x653800185911 <unknown>
#14 0x65380016e185 <unknown>
#15 0x653800186492 <unknown>
#16 0x6538001532ef <unknown>
#17 0x6538001a5e88 <unknown>
#18 0x6538001a6053 <unknown>
#19 0x6538001b5ddc <unknown>
#20 0x70968ce9ca94 <unknown>
#21 0x70968cf29c3c <unknown>

[2024-10-10 20:58:19] [INFO    ] discord.gateway: Shard ID None has successfully RESUMED session 7c5250b8836853f365b0a930880c9381.
[2024-10-10 23:47:05] [INFO    ] discord.gateway: Shard ID None has successfully RESUMED session 7c5250b8836853f365b0a930880c9381.
[2024-10-11 02:18:41] [INFO    ] discord.gateway: Shard ID None has successfully RESUMED session 7c5250b8836853f365b0a930880c9381.
[2024-10-11 02:38:50] [INFO    ] discord.gateway: Shard ID None has successfully RESUMED session 7c5250b8836853f365b0a930880c9381.
[2024-10-11 03:14:45] [INFO    ] discord.gateway: Shard ID None has successfully RESUMED session 7c5250b8836853f365b0a930880c9381.
[2024-10-11 03:44:20] [INFO    ] discord.gateway: Shard ID None has successfully RESUMED session 7c5250b8836853f365b0a930880c9381.
[2024-10-11 05:03:47] [INFO    ] discord.gateway: Shard ID None has successfully RESUMED session 7c5250b8836853f365b0a930880c9381.
[2024-10-11 06:51:43] [INFO    ] discord.gateway: Shard ID None has successfully RESUMED session 7c5250b8836853f365b0a930880c9381.
[2024-10-11 10:39:35] [INFO    ] discord.gateway: Shard ID None has successfully RESUMED session 7c5250b8836853f365b0a930880c9381.
[2024-10-11 11:09:56] [INFO    ] discord.gateway: Shard ID None has successfully RESUMED session 7c5250b8836853f365b0a930880c9381.
[2024-10-11 13:03:21] [INFO    ] discord.gateway: Shard ID None has successfully RESUMED session 7c5250b8836853f365b0a930880c9381.
[2024-10-11 15:39:06] [INFO    ] discord.gateway: Shard ID None has successfully RESUMED session 7c5250b8836853f365b0a930880c9381.
[2024-10-11 16:27:09] [ERROR   ] discord.client: Ignoring exception in on_message
Traceback (most recent call last):
  File "/mnt/2tbdrive/projects/RoyBot/venv/lib/python3.12/site-packages/discord/client.py", line 449, in _run_event
    await coro(*args, **kwargs)
  File "/mnt/2tbdrive/projects/RoyBot/src/main.py", line 19, in on_message
    await messages.handle_message(client, message)
  File "/mnt/2tbdrive/projects/RoyBot/src/handlers/messages.py", line 22, in handle_message
    image_generator.generate_message_jpg(original, message.author.display_name, message.author.display_avatar.url)
  File "/mnt/2tbdrive/projects/RoyBot/src/image_generator.py", line 44, in generate_message_jpg
    message_box.send_keys(message)
  File "/mnt/2tbdrive/projects/RoyBot/venv/lib/python3.12/site-packages/selenium/webdriver/remote/webelement.py", line 231, in send_keys
    self._execute(
  File "/mnt/2tbdrive/projects/RoyBot/venv/lib/python3.12/site-packages/selenium/webdriver/remote/webelement.py", line 395, in _execute
    return self._parent.execute(command, params)
           ^^^^^^^^^^^^^^^^^^^^^^^^^^^^^^^^^^^^^
  File "/mnt/2tbdrive/projects/RoyBot/venv/lib/python3.12/site-packages/selenium/webdriver/remote/webdriver.py", line 354, in execute
    self.error_handler.check_response(response)
  File "/mnt/2tbdrive/projects/RoyBot/venv/lib/python3.12/site-packages/selenium/webdriver/remote/errorhandler.py", line 229, in check_response
    raise exception_class(message, screen, stacktrace)
selenium.common.exceptions.WebDriverException: Message: unknown error: ChromeDriver only supports characters in the BMP
  (Session info: chrome=129.0.6668.100)
Stacktrace:
#0 0x64f4cdf19f8a <unknown>
#1 0x64f4cdc005e0 <unknown>
#2 0x64f4cdc8d2d4 <unknown>
#3 0x64f4cdc49b8d <unknown>
#4 0x64f4cdc48e66 <unknown>
#5 0x64f4cdc74b22 <unknown>
#6 0x64f4cdc44478 <unknown>
#7 0x64f4cdc74cee <unknown>
#8 0x64f4cdc93d7d <unknown>
#9 0x64f4cdc748c3 <unknown>
#10 0x64f4cdc426b3 <unknown>
#11 0x64f4cdc4368e <unknown>
#12 0x64f4cdee498b <unknown>
#13 0x64f4cdee8911 <unknown>
#14 0x64f4cded1185 <unknown>
#15 0x64f4cdee9492 <unknown>
#16 0x64f4cdeb62ef <unknown>
#17 0x64f4cdf08e88 <unknown>
#18 0x64f4cdf09053 <unknown>
#19 0x64f4cdf18ddc <unknown>
#20 0x76795c89ca94 <unknown>
#21 0x76795c929c3c <unknown>

[2024-10-11 16:45:13] [INFO    ] discord.gateway: Shard ID None has successfully RESUMED session 7c5250b8836853f365b0a930880c9381.
[2024-10-11 18:02:40] [ERROR   ] discord.client: Ignoring exception in on_message
Traceback (most recent call last):
  File "/mnt/2tbdrive/projects/RoyBot/venv/lib/python3.12/site-packages/discord/client.py", line 449, in _run_event
    await coro(*args, **kwargs)
  File "/mnt/2tbdrive/projects/RoyBot/src/main.py", line 19, in on_message
    await messages.handle_message(client, message)
  File "/mnt/2tbdrive/projects/RoyBot/src/handlers/messages.py", line 22, in handle_message
    image_generator.generate_message_jpg(original, message.author.display_name, message.author.display_avatar.url)
  File "/mnt/2tbdrive/projects/RoyBot/src/image_generator.py", line 44, in generate_message_jpg
    message_box.send_keys(message)
  File "/mnt/2tbdrive/projects/RoyBot/venv/lib/python3.12/site-packages/selenium/webdriver/remote/webelement.py", line 231, in send_keys
    self._execute(
  File "/mnt/2tbdrive/projects/RoyBot/venv/lib/python3.12/site-packages/selenium/webdriver/remote/webelement.py", line 395, in _execute
    return self._parent.execute(command, params)
           ^^^^^^^^^^^^^^^^^^^^^^^^^^^^^^^^^^^^^
  File "/mnt/2tbdrive/projects/RoyBot/venv/lib/python3.12/site-packages/selenium/webdriver/remote/webdriver.py", line 354, in execute
    self.error_handler.check_response(response)
  File "/mnt/2tbdrive/projects/RoyBot/venv/lib/python3.12/site-packages/selenium/webdriver/remote/errorhandler.py", line 229, in check_response
    raise exception_class(message, screen, stacktrace)
selenium.common.exceptions.WebDriverException: Message: unknown error: ChromeDriver only supports characters in the BMP
  (Session info: chrome=129.0.6668.100)
Stacktrace:
#0 0x5b2829c09f8a <unknown>
#1 0x5b28298f05e0 <unknown>
#2 0x5b282997d2d4 <unknown>
#3 0x5b2829939b8d <unknown>
#4 0x5b2829938e66 <unknown>
#5 0x5b2829964b22 <unknown>
#6 0x5b2829934478 <unknown>
#7 0x5b2829964cee <unknown>
#8 0x5b2829983d7d <unknown>
#9 0x5b28299648c3 <unknown>
#10 0x5b28299326b3 <unknown>
#11 0x5b282993368e <unknown>
#12 0x5b2829bd498b <unknown>
#13 0x5b2829bd8911 <unknown>
#14 0x5b2829bc1185 <unknown>
#15 0x5b2829bd9492 <unknown>
#16 0x5b2829ba62ef <unknown>
#17 0x5b2829bf8e88 <unknown>
#18 0x5b2829bf9053 <unknown>
#19 0x5b2829c08ddc <unknown>
#20 0x70983f49ca94 <unknown>
#21 0x70983f529c3c <unknown>

[2024-10-11 18:05:52] [INFO    ] discord.gateway: Shard ID None has successfully RESUMED session 7c5250b8836853f365b0a930880c9381.
[2024-10-11 20:29:06] [ERROR   ] discord.client: Ignoring exception in on_message
Traceback (most recent call last):
  File "/mnt/2tbdrive/projects/RoyBot/src/handlers/messages.py", line 33, in handle_message
    await message.reply(f"# ðŸš¨ROY ALERTðŸš¨\nroy #{roy_counter.roy_count}", file=discord.File(new_path))
  File "/mnt/2tbdrive/projects/RoyBot/venv/lib/python3.12/site-packages/discord/message.py", line 1564, in reply
    return await self.channel.send(content, reference=self, **kwargs)
           ^^^^^^^^^^^^^^^^^^^^^^^^^^^^^^^^^^^^^^^^^^^^^^^^^^^^^^^^^^
  File "/mnt/2tbdrive/projects/RoyBot/venv/lib/python3.12/site-packages/discord/abc.py", line 1618, in send
    data = await state.http.send_message(channel.id, params=params)
           ^^^^^^^^^^^^^^^^^^^^^^^^^^^^^^^^^^^^^^^^^^^^^^^^^^^^^^^^
  File "/mnt/2tbdrive/projects/RoyBot/venv/lib/python3.12/site-packages/discord/http.py", line 758, in request
    raise HTTPException(response, data)
discord.errors.HTTPException: 400 Bad Request (error code: 50035): Invalid Form Body
In message_reference: Unknown message

During handling of the above exception, another exception occurred:

Traceback (most recent call last):
  File "/mnt/2tbdrive/projects/RoyBot/venv/lib/python3.12/site-packages/discord/client.py", line 449, in _run_event
    await coro(*args, **kwargs)
  File "/mnt/2tbdrive/projects/RoyBot/src/main.py", line 19, in on_message
    await messages.handle_message(client, message)
  File "/mnt/2tbdrive/projects/RoyBot/src/handlers/messages.py", line 37, in handle_message
    await message.reply(f"# ðŸš¨ROY ALERTðŸš¨\nroy #{roy_counter.roy_count}")
  File "/mnt/2tbdrive/projects/RoyBot/venv/lib/python3.12/site-packages/discord/message.py", line 1564, in reply
    return await self.channel.send(content, reference=self, **kwargs)
           ^^^^^^^^^^^^^^^^^^^^^^^^^^^^^^^^^^^^^^^^^^^^^^^^^^^^^^^^^^
  File "/mnt/2tbdrive/projects/RoyBot/venv/lib/python3.12/site-packages/discord/abc.py", line 1618, in send
    data = await state.http.send_message(channel.id, params=params)
           ^^^^^^^^^^^^^^^^^^^^^^^^^^^^^^^^^^^^^^^^^^^^^^^^^^^^^^^^
  File "/mnt/2tbdrive/projects/RoyBot/venv/lib/python3.12/site-packages/discord/http.py", line 758, in request
    raise HTTPException(response, data)
discord.errors.HTTPException: 400 Bad Request (error code: 50035): Invalid Form Body
In message_reference: Unknown message
[2024-10-11 21:29:45] [INFO    ] discord.gateway: Shard ID None has successfully RESUMED session 7c5250b8836853f365b0a930880c9381.
[2024-10-11 22:15:48] [INFO    ] discord.gateway: Shard ID None has successfully RESUMED session 7c5250b8836853f365b0a930880c9381.
[2024-10-11 23:53:10] [INFO    ] discord.gateway: Shard ID None has successfully RESUMED session 7c5250b8836853f365b0a930880c9381.
[2024-10-12 03:33:03] [INFO    ] discord.gateway: Shard ID None has successfully RESUMED session 7c5250b8836853f365b0a930880c9381.
[2024-10-12 06:26:48] [INFO    ] discord.gateway: Shard ID None has successfully RESUMED session 7c5250b8836853f365b0a930880c9381.
[2024-10-12 10:09:31] [INFO    ] discord.gateway: Shard ID None has successfully RESUMED session 7c5250b8836853f365b0a930880c9381.
[2024-10-12 12:41:06] [INFO    ] discord.gateway: Shard ID None has successfully RESUMED session 7c5250b8836853f365b0a930880c9381.
[2024-10-12 14:48:46] [INFO    ] discord.gateway: Shard ID None has successfully RESUMED session 7c5250b8836853f365b0a930880c9381.
[2024-10-12 17:11:36] [INFO    ] discord.gateway: Shard ID None has successfully RESUMED session 7c5250b8836853f365b0a930880c9381.
[2024-10-12 19:18:10] [INFO    ] discord.gateway: Shard ID None has successfully RESUMED session 7c5250b8836853f365b0a930880c9381.
